Workbook
Name proc: #REF!

Sheet Template change log & approval
B2: GTS MANAGEMENT SYSTEM
B4: URS Generic WBS, OBS and RACI Matrix
B6: 83410775-PRJ-CAN-EN-012 | L6: Template
B10: Please refer to GTS Management System for: • The process activity to which this document is attached • The criteria (country, company…) applicable to this document • The latest version in force, unless otherwise specified in your context
B11: If you cannot find this document in GTS Management System, it means that it is not applicable to you.
B14: Abstract
B15: The generic WBS, OBS and RACI matrix to be used for URS projects. The generic templates provided in this document will need to be adapted to the specific project needs.
B18: Log of changes
B19: Revision | C19: Description | L19: Publication date
B20: 001 | C20: First Issue Peer review reference: TCTS-CHR-15-007 | L20: 42062
B21: 002 | C21: Generic CBS tab added. Generic WBS L6 tab added | L21: 42283
B22: 003 | C22: Modified the flow chart for Generic OBS-Domestic and Generic OBS-Export. Removed the revision level on the top right of the embedded Chart on the Generic OBS and CBS. Changed Written By Name. Updated tailoring tab | L22: 42403
B23: 004 | C23: In support of CR 038790 : Generic WBSL6 tab: Added WBS activity 1.1.7 Non-Technical Requirements Management WBS Instructions: Removed document Revision numbers & added comment for table to be checked. Generic OBS – Domestic tab: OBS updated to include DDQS Stakeholders and reflect changes in Engineering & Services Project Organization. Generic OBS – Export tab: tab removed. Generic RACI tab: Added R&O Management, & Non-Technical Requiremnts Mgt Tailoring Sheet : tab removed Log of changes and approval: removed as duplication from Abstract & Log of changes tab | L23: 42864
B24: 005 | C24: Migration to new Template All tabs modified to include new Solution Deployment and Services (SDS) Organization Further engineering WBS/CBS/RACI changes to come in revision 006 of this document. | L24: 42990
B25: 006 | C25: Generic OBS: removal of ATS role. Addition of PPTM role. R&O Manager outside of POM responsibility. HSE Manager from PM's responsibility to Deployment Manager's responsibility. Generic WBSL5: Removal of costs placeholders "Contigencies" & "Others like Direct Selling Costs". Merge of Solution Engineering & System IVVQ Workpackages. Sligth amendments to Solution Deployment workpackage. Generic WBS: Visio reflecting changes to Generic WBSL5 tab Generic CBS: Visio reflecting changes to Generic WBSL5 tab Generic RACI: Table reflecting changes brought to the OBS & WBS WBS Instructions: table reflecting changes brought to the WBS | L25: 43131
B26: 007 | C26: Generic WBS & Generic CBS: update of WBS 5.1.2 from "Schedule Management" to "Schedule & Resource Management" Generic WBSL5: update of tab title from "WBS L6 for URS Projects" to "WBS L5 for URS Projects". Some activities renamed & renumbered, please refer to column F "Changes from previous WBS". Generic WBSL5: update of the WBS dictionnary Generic WBS, Generic WBSL5 & Generic CBS: WP 2.5 Cyber Security split in 2 WP. Generic OBS: Addition of 3 roles (Cyber Sec Authority, Cyber Sec Eng Manager, Cyber Sec Assurance Manager) and Technical Interface Leader. Adjustments in dotted lines/full lines for Safety Authority, Safety Assurance and Quality Assurance. Generic RACI: Addition of Cyber Security WPs & OBS roles. Generic CBS: Addition of "Project Closure" placeholders. | L26: 43235
B27: 008 | C27: Generic WBS: Visio limited to WBS L2 workpackages. Detailed WBS: consolidation of procurement activities under WP1.4 (activities "3.8.2.6 OnBoard Material Procurement" and "3.8.3.6 WS/Central Material Procurement" have been removed. Detailed WBS, Generic CBS, Generic RACI: Remove Stakeholders Mgt & NTR Mgt in WP1. Generic OBS & Generic RACI : Addition of Chief Engineer role. Detailed WBS : Update of Safety Engineering & RAM Engineering WPs breakdown. Generic WBS, Detailed WBS, Generic CBS, Generic RACI: Project Configuration Management merge into 3.1.5 Solution Configuration Management. Configuration Manager reporting to SEM and Site Configuration Manager reporting to Deployment Project Manager. Generic WBS, Detailed WBS, Generic CBS, Generic RACI: Cost Control Management moved from 1.1.1 to 1.2. Generic WBS, Detailed WBS, Generic CBS, Generic RACI: Transfer of Cyber Security development from WP 2 to WP 3.9. Generic WBS, Detailed WBS, Generic CBS, Generic RACI: changes to Solutions Deployment WPs (Additional breakdown to Infrastructure Design, Addition of Warehouse & Logistic and Decommissioning WPs, Split T&C from Deployment) & Services WP (removal Customer Support Mgt WP) Detailed WBS: more breakdown provided to Operations Training & Maintenance Training. Generic WBS, Detailed WBS, Generic CBS, Generic RACI: Specialty Engineering created & left blank. Will be used in the future for non-core CBTC activities like Artificial Intelligence or Bid Data Analytics. Generic OBS: Safety Engineering Manager has been renamed Project Safety Manager Closure CR052329 | L27: 43524
B28: 009 | C28: Generic WBS, Detailed WBS, Generic CBS, Generic RACI: WP2 renamed to Technical Safety Generic OBS: changes in Safety OBS Generic RACI: Safety Authority & Project Design Authority are ""(C)onsuled" regarding "Independent Validation" artefacts (CR052044) Generic WBS, Detailed WBS, Generic CBS, Generic RACI: WP1.6 Project Configuration Management added Generic WBS, Detailed WBS, Generic CBS, Generic RACI: WP3.9b Cyber IT Design added (and System Platform Software & Integration renumbered 3.9a) Detailed WBS : limitation of WP3 to WBS Level 2 activities. Generic OBS: Chief Engineer has been ranmed Chief Engineering Architect due to local regulations | L28: 44229
B29: 010 | C29: Generic WBS, Detailed WBS, Generic CBS, Generic RACI: WP4 created which consolidates DCS, Network & Cyber activities. (WP to be either WP3.8 or WP4 depending on a set of rules captured on the right of the WBS & CBS) Generic WBS, Detailed WBS, Generic CBS, Generic RACI: Training WP transferred from 5.1 to WP 5.9. Generic WBS, Detailed WBS, Generic CBS, Generic RACI: Publication & Archives WP transferred from 5.1 to WP1.6. Generic WBS, Detailed WBS, Generic CBS, Generic RACI : Project Configuration Management WP removed Generic OBS and Generic RACI: changes to Deployment OBS Generic OBS and Generic RACI: Safety OBS updated Generic WBS, Detailed WBS, Generic CBS: changes in WP3 Engineering Workpackages | L29: 44617
B30: 011 | C30: Detailed WBS: changes in details of WP 4.1 Generic OBS: correction in the dotted line reporting of SAM to PSM Generic OBS: Project Admin & Publications are reporting to the Data Manager. Detailed WBS: Deletion of "Test & Commissioning Support" activity which should not have been listed. | L30: 44740
B31: 012 | C31: Updated to Hitachi template as per QUAL-5663 | L31: 45805
B34: Internal signature
B35: Actor | C35: Role / Job title | G35: Name | J35: Signature | L35: Signature date
B36: Written by | C36: URS PMO Manager | G36: Thomas Delevacque | L36: 44740
B37: Verified by | C37: CCM | G37: Patricia Lavergne | L37: 44740
B38: Approved by | C38: 5.2 CPO | G38: Francois Coursault | L38: 44740
G44: Hitachi Rail – Internal
G45: This document may not be reproduced, modified, adapted, published, translated, in any way, in whole or in part, or disclosed to a third party without the prior written consent of HITACHI RAIL
G46: © Hitachi Rail Limited 2025. All rights reserved. | L46: Template: 87201589-QCI-GRP-EN-014

Sheet Generic WBS
A1: Generic WBS
A2: ='Template change log & approval'!$B$7&" - "&'Template change log & approval'!$G$7 -> -
J62: Hitachi Rail – Internal
J63: This document may not be reproduced, modified, adapted, published, translated, in any way, in whole or in part, or disclosed to a third party without the prior written consent of HITACHI RAIL
J64: © Hitachi Rail Limited 2025. All rights reserved. | O64: Template: 87201589-QCI-GRP-EN-014

Sheet Detailed WBS
B1: Detailed WBS for URS Projects
B2: ='Template change log & approval'!$B$7&" - "&'Template change log & approval'!$G$7 -> -
B3: (In red, changes from last revision) | G3: WBS Dictionary
A4: WBS Level | B4: WBS Code | C4: WBS Name | D4: Reports to | F4: Changes from previous WBS | G4: WBS activity Description | H4: Owner | I4: WBS input(s) | J4: WBS output(s) | K4: Quality Requirement(s) | L4: Acceptance Criteria | M4: Earned Value Definition (defined only at level 2)
A5: 0 | B5: 0 | C5: URS Transport Project
A6: =LEN(B6)-LEN(SUBSTITUTE(B6,".",""))+1 -> 1 | B6: 1 | C6: Program Management | D6: 0
A7: =LEN(B7)-LEN(SUBSTITUTE(B7,".",""))+1 -> 2 | B7: 1.1 | C7: Program Management | D7: =LEFT(B7,FIND("$",SUBSTITUTE(B7,".","$",LEN(B7)-LEN(SUBSTITUTE(B7,".",""))),1)-1) -> 1 | G7: • Management baseline and plan (WBS/OBS/work-packages, schedule, cost estimates, risks, data management, etc.) • Personnel management (skills, workloads, resources). • Program monitoring (status report, progress, cost, financing, etc.), performance report (progress report). | H7: PM Assisted by POM, Risk Manager, Data Manager & Project Assistant | I7: Notification to Proceed (NTP) Complete Bid Package WP agreements Project Management Plan (if any) | J7: Project Management Plan Deliverable CDRL list Customer & Internal Stakeholder reports (Project Schedule, Data Management Plan, Project Review Dashboard) Customer Sign-off - Provisional Acceptance Project Closeout Checklist | K7: Compliance to GTS MS Manage Project (5.2) process and re-use of Group or entity tools & template (WBS/OBS/work-packages,...) | L7: Continues throughout project to handover to SD&S Group for Warranty Services | M7: Level of Effort
A8: =LEN(B8)-LEN(SUBSTITUTE(B8,".",""))+1 -> 2 | B8: 1.2 | C8: Cost Control Management | D8: =LEFT(B8,FIND("$",SUBSTITUTE(B8,".","$",LEN(B8)-LEN(SUBSTITUTE(B8,".",""))),1)-1) -> 1 | G8: • Management cost baseline and financial reporting | H8: PCC | I8: WBS structure | J8: Project Review Dashboard | M8: Level of Effort
A9: =LEN(B9)-LEN(SUBSTITUTE(B9,".",""))+1 -> 2 | B9: 1.3 | C9: Contract Management | D9: =LEFT(B9,FIND("$",SUBSTITUTE(B9,".","$",LEN(B9)-LEN(SUBSTITUTE(B9,".",""))),1)-1) -> 1 | G9: • Preparation of contractual correspondence, notifications • Negotiation of penalties, contract changes, claims, commercial issues | H9: Contract Manager | I9: Contract documents, compliance matrix | J9: Project Close-out Checklist | M9: Level of Effort
A10: =LEN(B10)-LEN(SUBSTITUTE(B10,".",""))+1 -> 2 | B10: 1.4 | C10: Procurement | D10: =LEFT(B10,FIND("$",SUBSTITUTE(B10,".","$",LEN(B10)-LEN(SUBSTITUTE(B10,".",""))),1)-1) -> 1 | G10: • Make-or-buy strategy • Analysis and monitoring of procurement and supply chain risks / site quality control | H10: Acquisition Project Manager | I10: Bid Package including schedule, equipment list, technical requirements Contractual requirements | J10: Project Procurement Plan IPP (cost, lead time, risks, supplier strategy, export restrictions) Inspection and Testing Plan | M10: Level of Effort
A11: =LEN(B11)-LEN(SUBSTITUTE(B11,".",""))+1 -> 2 | B11: 1.5 | C11: Quality Assurance | D11: =LEFT(B11,FIND("$",SUBSTITUTE(B11,".","$",LEN(B11)-LEN(SUBSTITUTE(B11,".",""))),1)-1) -> 1 | G11: • All quality activities across entire program system:, quality assurance, auditing. • Monitoring of norms and standards applicable to the contract | H11: Quality Manager | I11: Contract documents, compliance matrix | J11: Quality Plan Audit, Assessment, and Analysis Report | M11: Level of Effort
A12: =LEN(B12)-LEN(SUBSTITUTE(B12,".",""))+1 -> 2 | B12: 1.6 | C12: Publications and Archives | D12: =LEFT(B12,FIND("$",SUBSTITUTE(B12,".","$",LEN(B12)-LEN(SUBSTITUTE(B12,".",""))),1)-1) -> 1 | F12: moved from 5.2 | G12: • Publication & Archiving of Internal documentation | H12: Publications WPM | J12: Publication and archiving of documents
A13: =LEN(B13)-LEN(SUBSTITUTE(B13,".",""))+1 -> 1 | B13: 2 | C13: Technical Safety | D13: 0
A14: =LEN(B14)-LEN(SUBSTITUTE(B14,".",""))+1 -> 2 | B14: 2.1 | C14: Safety Engineering | D14: =LEFT(B14,FIND("$",SUBSTITUTE(B14,".","$",LEN(B14)-LEN(SUBSTITUTE(B14,".",""))),1)-1) -> 2 | G14: • Conduct hazard identification studies (HAZOP/HAZID) and hazard analyses (FHA, FTA) and derive safety requirements. • Perform safety design reviews (system, software and hardware) and safety analyses to ensure compliance to safety design principles and requirements. • Review verification and validation plans, test procedures and reports to confirm coverage by test and analysis. • Record and track hazards (Hazard Log), control measures, design and verification and validation evidence and confirm the hazard risks are tolerable. • Prepare safety appraisals, safety cases (design and implementation) and safety memos to demonstrate the system is safe for its intended purpose. | H14: Safety Engineering Manager | I14: Project Management Plan, SEMP, SW Dev Plan, HwEM Plan, Sys Data Mgt Plan, Sys Verification plan, Sys Validation plan, System Test Plan Customer Requirements Specification, System Architecture Specification, System Requirements Specification, Subsystem Requirements Specification Interface Control Documents System Detailed Design Operation Manuals and Guides Test Procedures, Test Reports Migration Plan Software Architecture Specification, Software Detail Design Hardware Requirements Specification, Hardware Detail Design, Hardware Schematics, Interface Schematics, Wiring Drawings | J14: System Safety Plan Preliminary Hazard Analysis System Hazard Analysis Interface Hazard Analysis HAZOP/HAZID Reports Functional Safety Analyses Hardware Safety Studies Software Safety Studies FMEA/FMECA Reports Fault Tree Analysis Hazard Log Safety-related Application Conditions Report Safety Cases/Reports (product, platform, generic application, specific application – design and implementation) Technical Support - Integrated Design Team, Safety Design Reviews Support CCRB/PCRs Review and Approve Documents – Plans, Test Procedures Safety Analyses and White Papers | L14: Delivery of safety case and approval of safety certificate by Safety Authority URS.
A15: =LEN(B15)-LEN(SUBSTITUTE(B15,".",""))+1 -> 2 | B15: 2.2 | C15: Safety Assurance | D15: =LEFT(B15,FIND("$",SUBSTITUTE(B15,".","$",LEN(B15)-LEN(SUBSTITUTE(B15,".",""))),1)-1) -> 2 | G15: Assure the safety of our delivered solutions by performing Safety Assurance Gate Reviews (SAGRs), independent safety audits/assessments, and Root Cause Analysis (RCA) investigations (as needed) for commercial projects and for internal product development in order to identify issues related to technical safety and applied processes. | H15: Safety Assurance Manager | I15: RAM and Safety Plans Engineering Plans (including System Design, System Operations, HW and SW) IVQ Plans Safety and Hazard Analyses Safety Case | J15: Internal Safety Assurance Plan (per project or product) Safety Assurance Gate Review (SAGR) Checklist SAGR Findings Log Internal Safety Audit/Assessment Report Safety Certification Readiness Review (SCRR) Checklist Root Cause Analysis Report (if required) | K15: CENELEC Standards - EN 50126-1:1999, EN 50128:2011, EN 50129:2003, EN 50157:2010 AREMA IEE 1474.1 | L15: - Internal Safety Assurance Plan approved by Safety Assurance director - Applicable DDQS gate passes with Safety Assurance acceptance - Internal Safety Audit/Assessment Reportapproved by Safety Assurance director - Safety Authority and, if applicable), external ISA acceptance of the safety case. - Root Cause Analysis Report approved by Safety Assurance director and the Hitachi Rail GTS Canada Safety Authority.
A16: =LEN(B16)-LEN(SUBSTITUTE(B16,".",""))+1 -> 2 | B16: 2.3 | C16: RAMT (RAM & Testability) | D16: =LEFT(B16,FIND("$",SUBSTITUTE(B16,".","$",LEN(B16)-LEN(SUBSTITUTE(B16,".",""))),1)-1) -> 2 | G16: • Perform RAM analyses to confirm system performance and compliance to RAM targets. • Review system architecture and hardware design (FMEA/CA) to identify Single Point Failures (SPF) and Common Cause Failures (CCF). • Perform Testability Analysis to evaluate the fault detection and isolation coverage. • Perform Spare Parts Analysis for the system warranty period/system life. • Monitor the system performance during the demonstration period and produce reports. | H16: RAM Manager | I16: System Architecture Specification, System Requirements Specification, Hardware Requirements Specification Hardware Detail Design, Hardware Schematics Interface Schematics, Wiring Drawings Equipment Layout, Bill of Material, Equipment Family Tree Component/Part Hardware Specifications Operation Manuals and Guides | J16: RAM Plan RAM Analysis Spare Parts Analysis Special Tools and Equipment List Testability Analysis System FMEA/CA RAM Demonstration Plan RAM Demonstration Report | L16: Approval of applicable RAM documents by Design Authority and Project Manager.
A17: =LEN(B17)-LEN(SUBSTITUTE(B17,".",""))+1 -> 2 | B17: 2.4 | C17: Independent Validation | D17: =LEFT(B17,FIND("$",SUBSTITUTE(B17,".","$",LEN(B17)-LEN(SUBSTITUTE(B17,".",""))),1)-1) -> 2 | G17: Provides objective confirmation that a solution {element} is suitable for the intended operation in the intended environment by using planned analyses, based on evidence, to support a judgment regarding satisfaction of stakeholders’ expectations, particularly those for RAMS and Quality, as part of a determination of its overall fitness for purpose. | H17: Independent Validator | I17: Design Validation(s) (and Design Justification Files), Operational Concept Description(s), Service File(s), Verification Plan(s), Engineering Management Plan(s), Project (and Work Package) Management Plan(s), Quality Assurance Plan(s), Configuration Management Plan(s), Safety Plan(s), RAM Plan(s), Product Breakdown Structure, Quality Management Report(s), Configuration Management Report(s), Hazard Log(s), RAM Analyses Engineering Reviews Records & referenced artefacts | J17: Solution Validation Plan Solution Validation Report | K17: Validation objectives of CENELEC standards - EN50126-1:2017, EN50126-2:2017, EN50128:2011, EN50129:2018 (including applicable corrigenda and normative references) Validation objectives of IEEE standard - 1012:2016 (including applicable corrigenda and normative references) | L17: Validation Plan agreed by Safety Authority Validation Report taken into account in Safety Case
A18: =LEN(B18)-LEN(SUBSTITUTE(B18,".",""))+1 -> 1 | B18: 3 | C18: Solution Engineering | D18: 0
A19: =LEN(B19)-LEN(SUBSTITUTE(B19,".",""))+1 -> 2 | B19: 3.1 | C19: Project Engineering Management (PEM) | D19: =LEFT(B19,FIND("$",SUBSTITUTE(B19,".","$",LEN(B19)-LEN(SUBSTITUTE(B19,".",""))),1)-1) -> 3 | F19: Renamed/added to group PEM workpackages | H19: Project Management Director | I19: Project Management Plan BID Package (Engineering Cost Estimate, Requirement Compliance Matrix, DVA) WPA Engineering Project Schedule R&O register DVA | J19: Solution Engineering Management Plan (SEMP) WPA per Engineering WP Engineering Dashboard Contribution to: Project Schedule Contribution to: R&O Register DVA Validation of DDQS Reviews
A20: =LEN(B20)-LEN(SUBSTITUTE(B20,".",""))+1 -> 3 | B20: 3.1.1 | C20: Solution Engineering Manager (SEM) | D20: =LEFT(B20,FIND("$",SUBSTITUTE(B20,".","$",LEN(B20)-LEN(SUBSTITUTE(B20,".",""))),1)-1) -> 3.1 | G20: • Management Engineering baseline and plan (WBS/OBS/work-packages, schedule, cost estimates, risks, etc.) • Resource management (skills, workloads). • Engineering WP monitoring (status report, progress, cost, financing, etc.), performance report (progress report). • Management of the overall Engineering WP Schedule • Calculation & Monitoring of the critical path • update of Budget, ETC and EAC forecasts per CBS based on WPM inputs • Overall Engineering WP responsibility and lead role for opportunities and risk management efforts. | H20: PEM Director | I20: Project Management Plan BID Package (Engineering Cost Estimate) WPA Engineering Project Schedule R&O register | J20: Solution Engineering Management Plan (SEMP) WPA per Engineering WP Engineering Dashboard Contribution to: Project Schedule Contribution to: R&O Register
A21: =LEN(B21)-LEN(SUBSTITUTE(B21,".",""))+1 -> 3 | B21: 3.1.2 | C21: Project Design Authority (PDA) | D21: =LEFT(B21,FIND("$",SUBSTITUTE(B21,".","$",LEN(B21)-LEN(SUBSTITUTE(B21,".",""))),1)-1) -> 3.1 | G21: Authority role for Product design instantiation to the project - Guarantees the integrity, relevance and feasibility of the Bids and Projects technical content, in accordance with Product Policy, adequate product re-use, Make-or-Buy Strategy, as well as the maturity of the technologies employed and the adequate assignment of Engineering teams; Challenges the Solution, has a right of audit and can trigger and organize technical reviews accordingly; Has the right to participate to or even chair the main Solution technical/engineering reviews during the execution of the bid or project; Validates the technical Risks & Opportunities assessment; Validates the Solution design by signing the Design Validation (DVa); Alerts the Division TD as needed; | H21: PEM Director | I21: BID Package (Requirement Compliance Matrix, DVA) DVA | J21: Contribution to: Engineering Dashboard Contribution to: Project Schedule Contribution to: R&O Register DVA Validation of DDQS Reviews
A22: =LEN(B22)-LEN(SUBSTITUTE(B22,".",""))+1 -> 2 | B22: 3.2 | C22: Solution Configuration Management (SCM) | D22: =LEFT(B22,FIND("$",SUBSTITUTE(B22,".","$",LEN(B22)-LEN(SUBSTITUTE(B22,".",""))),1)-1) -> 3 | F22: Added. Extracted from WP3.1 | G22: – Ensures that products comply with their requirements and are identified and documented in sufficient details to support the product life cycle, – Assures accurate product configuration information and enables product interchangeability, safe product operation and maintenance, – Facilitates orderly identification of product attributes and provides control of product information and product changes used to improve capabilities; correct deficiencies; improve performance, reliability, or maintainability; extend product life; or reduce cost, risk or liability. | H22: Configuration Manager | I22: Contract documents, compliance matrix, scope split with partners / customer, original proposal's CM estimates. WPA PBS (if available from the bid phase) Configuration Management Plan | J22: * Input to Work Package Agreement * Configuration Management Plans * Input to Statement/s of Work * CM inputs (or review of CM related content) to other plans such as PMP, SEMP, QAP and etc * Project associated CM metrics and KPIs * CMP implementation * Configuration Identification (solution baselines management in CM tool) * Participation in CCBs * Configuration Status Accounting for solution level (examples: As-Delivered Data Management, CM input to Data Packs, SVDD input and etc.) * Configuration Verification & Audit (FCA & PCA, HW ECNs and FCB CM's reviews)
A23: =LEN(B23)-LEN(SUBSTITUTE(B23,".",""))+1 -> 2 | B23: 3.3 | C23: Systems Engineering | D23: =LEFT(B23,FIND("$",SUBSTITUTE(B23,".","$",LEN(B23)-LEN(SUBSTITUTE(B23,".",""))),1)-1) -> 3 | F23: WP added to group Systems Design, Signalling Design & Network Design
A24: =LEN(B24)-LEN(SUBSTITUTE(B24,".",""))+1 -> 3 | B24: 3.3.1 | C24: Systems Design | D24: =LEFT(B24,FIND("$",SUBSTITUTE(B24,".","$",LEN(B24)-LEN(SUBSTITUTE(B24,".",""))),1)-1) -> 3.3 | G24: • Product System Specification and Design instantiation to the project -OCD, functional design and analysis, requirements definition, SSS, SSDD, ICD, IRS, alarms, parameters, -technical support to SW, HW, IVQ, Safety, Site etc. | H24: System Engineering Manager (SysEM/WPM) | I24: SEMP WPA Bid Package (Requirement Compliance Matrix, DVA) Customer specification Project Schedule R&O Register Product model, product SSS, SSDD, CD, IRS, alarms, parameters, product PCRs, | J24: OCD, SSSs, SSDDs (SyRS, SyDD, SAS), alarms, parameters, ICDs, IRS. SysDes VDD Traceability Customer Requirement up to Sub-System level Specification Contribution to: Engineering Dashboard, Project Schedule, R&O Register
A25: =LEN(B25)-LEN(SUBSTITUTE(B25,".",""))+1 -> 3 | B25: 3.3.2 | C25: Signalling Design | D25: =LEFT(B25,FIND("$",SUBSTITUTE(B25,".","$",LEN(B25)-LEN(SUBSTITUTE(B25,".",""))),1)-1) -> 3.3 | G25: • Product System Data Design instantiation to the project. - Defining the System Data Specification based on the System Design Requirements. - Defining Tool Requirements for tools used in the data design and configuration activities. - Producing a System Performance Analysis report. - Produce block designs, control tables, and system data input and export files. | H25: System Engineering Manager (SysEM/WPM) | I25: SEMP WPA Bid Package (Requirement Compliance Matrix, DVA) Product SDS, product B-rules, | J25: System Data Management Plan, System Data Specification, Safe Braking Model, Track Block Designs, Control Tables, System Performance Analysis, SPSIM software, Data Management Toolset, System Database. Contribution to: Engineering Dashboard, Project Schedule, R&O Register
B26: 3.4 | C26: Software Engineering | D26: =LEFT(B26,FIND("$",SUBSTITUTE(B26,".","$",LEN(B26)-LEN(SUBSTITUTE(B26,".",""))),1)-1) -> 3 | F26: WP added to group SW workpackages
A27: =LEN(B27)-LEN(SUBSTITUTE(B27,".",""))+1 -> 3 | B27: 3.4.1 | C27: Vehicle Software | D27: =LEFT(B27,FIND("$",SUBSTITUTE(B27,".","$",LEN(B27)-LEN(SUBSTITUTE(B27,".",""))),1)-1) -> 3.4 | G27: • Product Vehicle Software instanciation to the project. - contribution to SRS/IRS (as part of Sub-System specification) - full responsability of Sw design, Sw coding,Sw/Sw integration - contribution to STP/STR (as part of the Sub-System verification) | H27: Vehicle Sofware Engineering Manager (SwEM/WPM) | I27: SEMP WPA Compliance matrix Build Plan/Schedule Sub-System level specifcation (SyDD) System Database (neutral files) System Architecture Document | J27: SDP (one applicable for all SW) SRS/IRS (contribution) , SDD/IDD, Code, Unit/Module test, STP/STR (contribution) Traceability to code / test (as defined in CENELEC) VDD
A28: =LEN(B28)-LEN(SUBSTITUTE(B28,".",""))+1 -> 3 | B28: 3.4.2 | C28: Wayside Software | D28: =LEFT(B28,FIND("$",SUBSTITUTE(B28,".","$",LEN(B28)-LEN(SUBSTITUTE(B28,".",""))),1)-1) -> 3.4 | G28: • Product Wayside Sofware instanciation to the project. - contribution to SRS/IRS (as part of Sub-System specification) - full responsability of Sw design, Sw coding, Sw/Sw integration - contribution to STP/STR (as part of the Sub-System verification) | H28: Wayside Software Engineering Manager (SwEM/WPM) | I28: SEMP WPA Compliance matrix Build Plan/Schedule Sub-System level specifcation (SyDD) System Database (neutral files) System Architecture Document | J28: SDP (one applicable for all SW) SRS/IRS (contribution) , SDD/IDD, Code, Unit/Module test, STP/STR (contribution) Traceability to code / test (as defined in CENELEC) VDD
A29: =LEN(B29)-LEN(SUBSTITUTE(B29,".",""))+1 -> 3 | B29: 3.4.3 | C29: Central Software | D29: =LEFT(B29,FIND("$",SUBSTITUTE(B29,".","$",LEN(B29)-LEN(SUBSTITUTE(B29,".",""))),1)-1) -> 3.4 | G29: • Product Wayside Sofware instanciation to the project. - contribution to SRS/IRS (as part of Sub-System specification) - full responsability of Sw design, Sw coding, Sw/Sw integration - contribution to STP/STR (as part of the Sub-System verification) | H29: Central Software Engineering Manager (SwEM/WPM) | I29: SEMP WPA Compliance matrix Build Plan/Schedule Sub-System level specifcation (SyDD) System Database (neutral files) System Architecture Document | J29: SDP (one applicable for all SW) SRS/IRS (contribution) , SDD/IDD, Code, Unit/Module test, STP/STR (contribution) Traceability to code / test (as defined in CENELEC) VDD
A30: =LEN(B30)-LEN(SUBSTITUTE(B30,".",""))+1 -> 3 | B30: 3.4.4 | C30: Environment Simulator Software (ES) | D30: =LEFT(B30,FIND("$",SUBSTITUTE(B30,".","$",LEN(B30)-LEN(SUBSTITUTE(B30,".",""))),1)-1) -> 3.4 | F30: Added | G30: • Product Simulator Software instantiation to the project. - contribution to SRS/IRS (as part of Sub-System specification) - full responsibility of Sw design, Sw coding, Sw integration - contribution to STP/STR (as part of the Sub-System verification) | H30: Simulator Software Engineering Manager (SwEM/WPM) | I30: SEMP WPA Compliance Matrix Build plan /Schedule Sub-System level specification (SyDD) System Database (neutral files), IVVQ Test Plan, Lab Requirements. System Architecture Document | J30: SDP (one applicable for all SW) VDD, Simulator User Guide, Sub-System Simulator Requirements, Simulator Software applications utilizing the LDP and ECN process.
A31: =LEN(B31)-LEN(SUBSTITUTE(B31,".",""))+1 -> 3 | B31: 3.4.5 | C31: Software Verification | D31: =LEFT(B31,FIND("$",SUBSTITUTE(B31,".","$",LEN(B31)-LEN(SUBSTITUTE(B31,".",""))),1)-1) -> 3.4 | F31: Added | G31: Integration & Test of all the software components (Vehicle, Wayside, Central) before transter to the IVVQ team | H31: Simulator Software Engineering Manager (SwEM/WPM) | I31: SEMP WPA Compliance Matrix Build plan /Schedule Sub-System level specification (SyDD) System Database (neutral files), IVVQ Test Plan, Lab Requirements. System Architecture Document | J31: SDP (one applicable for all SW) VDD, Simulator User Guide, Sub-System Simulator Requirements, Simulator Software applications utilizing the LDP and ECN process.
A32: =LEN(B32)-LEN(SUBSTITUTE(B32,".",""))+1 -> 2 | B32: 3.5 | C32: Hardware Engineering | D32: =LEFT(B32,FIND("$",SUBSTITUTE(B32,".","$",LEN(B32)-LEN(SUBSTITUTE(B32,".",""))),1)-1) -> 3 | F32: Renamed | G32: • Product Hardware instantiation to the project (from the Specification to the Industrialisation and Qualification) • Cover the 3 domains : Vehicle HW, Wayside/Central (including DCS), and tools HW | H32: Hardware Engineering Director | I32: SEMP WPAs (could be 1 to 3 depending of the project complexity) System level specifcation for Hardware (HW) and Embedded Middleware (MW) | J32: . WPM documents (inputs to WPA, HEMP, Updated Schedule, HW Risk) . Design documents (HW and MW Requirements, HW and MW Detailed design, Electronic and Electrical Schematics/FPGA designs, Simulation analysis and FPGA test benches, Qualification test plans and reports, Interfaces Schematic diagrams) . Industrial documents (BOMs, assembly drawings, FAT procedure, Obsolescence management plan)
A33: =LEN(B33)-LEN(SUBSTITUTE(B33,".",""))+1 -> 3 | B33: 3.5.1 | C33: Vehicle Design | D33: =LEFT(B33,FIND("$",SUBSTITUTE(B33,".","$",LEN(B33)-LEN(SUBSTITUTE(B33,".",""))),1)-1) -> 3.5 | F33: Added | G33: Vehicle Product Hardware instantiation to the project (from the Specification to the Industrialisation and Qualification) | H33: Hardware Engineering Manager (HwEM/WPM) | I33: SEMP WPAs (could be 1 to 3 depending of the project complexity) System level specifcation for Hardware (HW) and Embedded Middleware (MW) | J33: . WPM documents (inputs to WPA, HEMP, Updated Schedule, HW Risk) . Design documents (HW and MW Requirements, HW and MW Detailed design, Electronic and Electrical Schematics/FPGA designs, Simulation analysis and FPGA test benches, Qualification test plans and reports, Interfaces Schematic diagrams) . Industrial documents (BOMs, assembly drawings, FAT procedure, Obsolescence management plan)
A34: =LEN(B34)-LEN(SUBSTITUTE(B34,".",""))+1 -> 3 | B34: 3.5.2 | C34: Wayside / Central Design | D34: =LEFT(B34,FIND("$",SUBSTITUTE(B34,".","$",LEN(B34)-LEN(SUBSTITUTE(B34,".",""))),1)-1) -> 3.5 | F34: Added | G34: Wayside/Central (including DCS) Product Hardware instantiation to the project (from the Specification to the Industrialisation and Qualification) | H34: Hardware Engineering Manager (HwEM/WPM) | I34: SEMP WPAs (could be 1 to 3 depending of the project complexity) System level specifcation for Hardware (HW) and Embedded Middleware (MW) | J34: . WPM documents (inputs to WPA, HEMP, Updated Schedule, HW Risk) . Design documents (HW and MW Requirements, HW and MW Detailed design, Electronic and Electrical Schematics/FPGA designs, Simulation analysis and FPGA test benches, Qualification test plans and reports, Interfaces Schematic diagrams) . Industrial documents (BOMs, assembly drawings, FAT procedure, Obsolescence management plan)
A35: =LEN(B35)-LEN(SUBSTITUTE(B35,".",""))+1 -> 3 | B35: 3.5.3 | C35: Hardware Tools | D35: =LEFT(B35,FIND("$",SUBSTITUTE(B35,".","$",LEN(B35)-LEN(SUBSTITUTE(B35,".",""))),1)-1) -> 3.5 | F35: Added | G35: Tools Product Hardware instantiation to the project (from the Specification to the Industrialisation and Qualification) | H35: Hardware Engineering Manager (HwEM/WPM) | I35: SEMP WPAs (could be 1 to 3 depending of the project complexity) System level specifcation for Hardware (HW) and Embedded Middleware (MW) | J35: . WPM documents (inputs to WPA, HEMP, Updated Schedule, HW Risk) . Design documents (HW and MW Requirements, HW and MW Detailed design, Electronic and Electrical Schematics/FPGA designs, Simulation analysis and FPGA test benches, Qualification test plans and reports, Interfaces Schematic diagrams) . Industrial documents (BOMs, assembly drawings, FAT procedure, Obsolescence management plan)
A36: =LEN(B36)-LEN(SUBSTITUTE(B36,".",""))+1 -> 3 | B36: 3.5.4 | C36: Hardware Compliance | D36: =LEFT(B36,FIND("$",SUBSTITUTE(B36,".","$",LEN(B36)-LEN(SUBSTITUTE(B36,".",""))),1)-1) -> 3.5 | F36: Added | G36: • Defines Hw IVQ strategy in consistency with that of upper level. • Tailors Hw I&V environment (process, practices and tools) according to Country/Company and project’s requirements. • Defines HW IVQ scenarios and guaranties their implementation. • Coordinates HW IVQ activities, establishes priorities and integration logical diagrams, conducts tests, supports factory and site acceptance as well as commissioning, analyses results and transmits them to development teams. • The HwIVQM may sometimes cumulate WPM role. | H36: HwVER / HwVAL (Hardware Integration Verification Qualification Manager (HwIVQM) As the HwEM’s delegate manages Hw Integration Verification & Qualification activities
A37: =LEN(B37)-LEN(SUBSTITUTE(B37,".",""))+1 -> 2 | B37: 3.6 | C37: Integration, Test and Verification (ITV) | D37: =LEFT(B37,FIND("$",SUBSTITUTE(B37,".","$",LEN(B37)-LEN(SUBSTITUTE(B37,".",""))),1)-1) -> 3 | F37: renumbered | G37: • Sub-System and System Requirement Inhouse verification • Inhouse System Operational Test • Site Commissioning Procedure Preparation | H37: IVVQ Manager or VV Manager (System and Subsystem VV Manager) | I37: SEMP WPA System and Sub-System specification (SyRS/SyDD or SSS/SRS) SW executable / VDD Integrated Test Environment | J37: System Verification and Validation Plan (SVVP) System Test Plan System / Sub-System Test Procedures (both inhouse and Site Procedures) System / Sub-System Test Reports, FAT Report SRVM (System Requirement Validation Matrix) System Acceptance and Commissiioning Report
A38: =LEN(B38)-LEN(SUBSTITUTE(B38,".",""))+1 -> 3 | B38: 3.6.1 | C38: Core CBTC Integration, Test and Verification (ATS/STC/VOBC) | D38: =LEFT(B38,FIND("$",SUBSTITUTE(B38,".","$",LEN(B38)-LEN(SUBSTITUTE(B38,".",""))),1)-1) -> 3.6 | F38: Added | G38: Core ITV – Integration, test and verification of each CBTC subsystem and requirement coverage verification. The major subsystems include ATS/SMC ZC/STC/VCC and VOBC | H38: IVVQ Manager or VV Manager (System and Subsystem VV Manager) | I38: SEMP WPA System and Sub-System specification (SyRS/SyDD or SSS/SRS) SW executable / VDD Integrated Test Environment | J38: System Verification and Validation Plan (SVVP) System Test Plan System / Sub-System Test Procedures (both inhouse and Site Procedures) System / Sub-System Test Reports, FAT Report SRVM (System Requirement Validation Matrix) System Acceptance and Commissiioning Report
A39: =LEN(B39)-LEN(SUBSTITUTE(B39,".",""))+1 -> 3 | B39: 3.6.2 | C39: Specialty Integration, Test and Verification (Specialty ITV) and Tools Engineering | D39: =LEFT(B39,FIND("$",SUBSTITUTE(B39,".","$",LEN(B39)-LEN(SUBSTITUTE(B39,".",""))),1)-1) -> 3.6 | F39: Added | G39: Specialty ITV – Integration, test and verification of supporting systems and tools. Supporting systems include DCS/ViewTrac and tools include the environment simulator and SGDG Tools Engineering – Any tools required internally and externally to support the CBTC solution. Internal tools such as the SGDG (data exports) and external tools to the customer such as ViewTrac, Cab Simulators etc. | H39: IVVQ Manager or VV Manager (System and Subsystem VV Manager) Tools SW developers | I39: SEMP WPA System and Sub-System specification (SyRS/SyDD or SSS/SRS) SW executable / VDD Integrated Test Environment | J39: System Verification and Validation Plan (SVVP) System Test Plan System / Sub-System Test Procedures (both inhouse and Site Procedures) System / Sub-System Test Reports, FAT Report SRVM (System Requirement Validation Matrix) System Acceptance and Commissiioning Report Production of customer tools (ViewTrac/Analytics) and internal tools (SGDG/SDM)
A40: =LEN(B40)-LEN(SUBSTITUTE(B40,".",""))+1 -> 2 | B40: 3.7 | C40: Product / Platform | D40: 0 | F40: Added | G40: Product activities and commitment of the Product team towards the Project. | H40: Product WPM | I40: Dva | J40: Product Platform Product documents
...

Sheet WBS Instructions
B1: WBS Instructions
B2: ='Template change log & approval'!$B$7&" - "&'Template change log & approval'!$G$7 -> -
B4: WBS Code | C4: WBS Name | D4: Description | E4: GTS MS 2.0 reference documents name | F4: Process # | G4: GTS MS 2.0 Reference #
B5: TCTS WBS | C5: TCTS WBS
B6: TCTS WBS.1 | C6: Program Management | E6: Manage Project CAN Procedure | F6: 5.2 | G6: 87200984-PRJ-GRP-EN | I6: Comments
B7: TCTS WBS.1.1 | C7: Program Management | D7: Including PMO activities, NTR management | E7: Manage Project CAN Procedure | F7: 5.2 | G7: 87200984-PRJ-GRP-EN | I7: Available on GTS MS Processes -> 5.2 PRJ -> Print
B8: TCTS WBS.1.2 | C8: Cost Control Management | D8: Cost Control activities | F8: 2.1
B9: TCTS WBS.1.3 | C9: Contract Management | D9: Contract Management activities | E9: Guide to contract Management Manage a contract (Procedure) | F9: 9.8 | G9: 87208528-LEG-GRP-EN 87201396-LEG-GRP-EN
B10: TCTS WBS.1.4 | C10: Procurement | D10: Labor at this level, material is handled at subsystem level | E10: Manage Acquisition CAN | F10: 7.1 | G10: 87201314-ACQ-GRP-EN | I10: Available on GTS MS Processes -> 7.1a ACQ -> Print
B11: TCTS WBS.1.5 | C11: Quality Assurance | D11: Quality Assurance Plan for an individual project | E11: Quality Assurance Plan | F11: 4.1 | G11: 87211389-QCI-GRP-EN
B12: TCTS WBS.1.6 | C12: Publications and Archives | D12: -Activities related to any document to be ECN'd and drawings and SW archiving | E12: Publication and Data Records Implementation Guideline | F12: 8.1 | G12: 83410362-DOC-CAN-EN
B13: TCTS WBS.2 | C13: Technical Safety
B14: TCTS WBS.2.1 | C14: Safety Engineering | D14: WPM activities - Safety Planning - Safety Management and Supervision All Safety Engineering activities performed at any stage and level of the project - Hazard Analyses - Hazard Management - Safety Analyses - Safety Case | E14: Manage a Work Package -Safety Management Instruction - Safety Planning Guideline Safety Instruction - Hazard Management - Identify and Analyze Hazards Process - Safety Case and Safety Approval Guideline - Safe Operating Requirements & Safety Application Conditions Guideline - Specific Hazard and Safety Analysis | F14: 5.2 6.1 4.1 | G14: 87201255-PRJ-GRP-EN 87204905-DDQ-GRP-EN 83410196-QCI-CAN-EN 83410224-QCI-CAN-EN 87204905-DDQ-GRP-EN 83410228-QCI-CAN-EN 83410226-QCI-CAN-EN 83410233-QCI-CAN-EN 83410234-QCI-CAN-EN 83410231-QCI-CAN-EN
B15: TCTS WBS.2.2 | C15: Safety Assurance | D15: All Safety Assurance activities performed at any stage and level of the project | E15: Safety Assurance Safety Management (Transportation specific) Systems Integration, Verification, Validation and Qualification Lifecycle Process Description | F15: 4.1 | G15: 87211146-QCI-GRP-EN 83410196-QCI-CAN-EN 83410305-DDQ-CAN-EN
B16: TCTS WBS.2.3 | C16: RAMT | D16: Activities related to the Specification and Demonstration of Dependability, Reliability, Availability, Maintainability and Safety (RAMS) | E16: RAM Management Guideline for RAM Planning | F16: 6.1 | G16: 83410195-DDQ-CAN-EN 83410350-SER-CAN-EN
B17: TCTS WBS.2.4 | C17: Independent Validation | D17: Activities related to the Independent Validation of the solution | E17: Independent Validation Governance Instruction | F17: 4.1 6.1 | G17: 83410894-QCI-CAN-EN | I17: Reference is (pending) governance instruction
B18: TCTS WBS.3 | C18: Solution Engineering
B19: TCTS WBS.3.1 | C19: Project Engineering Management | E19: Manage a Work Package | F19: 5.2 | G19: 87201255-PRJ-GRP-EN
B20: TCTS WBS.3.2 | C20: Solution Configuration Management
B21: TCTS WBS.3.3 | C21: Systems Engineering | D21: Solution design activities (specification, system architecture, operational concepts) | E21: Manage a Work Package Engineering reviews instruction Instruction for producing a Design & Justification File (D&JF) | F21: 5.2 6.1 6.1 | G21: 87201255-PRJ-GRP-EN 87201334-DDQ-GRP-EN 87201508-DDQ-GRP-EN
B22: TCTS WBS.3.4 | C22: Software Engineering | D22: Gathers all SW Subsystem development activities according to DDQS, including cost collector for material procurement | E22: Manage a Work Package Engineering reviews instruction Instruction for producing a Design & Justification File (D&JF) | F22: 5.2 6.1 6.1 | G22: 87201255-PRJ-GRP-EN 87201334-DDQ-GRP-EN 87201508-DDQ-GRP-EN
B23: TCTS WBS.3.5 | C23: Hardware Engineering | D23: Hardware Work Package Includes Vehicle/Wayside & Central HW Gathers all Hardware development activities according to DDQS | E23: Manage a Work Package Engineering reviews instruction Instruction for producing a Design & Justification File (D&JF) | F23: 5.2 6.1 6.1 | G23: 87201255-PRJ-GRP-EN 87201334-DDQ-GRP-EN 87201508-DDQ-GRP-EN
B24: TCTS WBS.3.6 | C24: Integration, Test and Verification | D24: ITV is about verification, validation & qualification activities performed at System level - All subsytem ITV activities are in the subsystem work packages. | E24: Manage a Work Package Engineering reviews instruction Instruction for producing a Design & Justification File (D&JF) Systems Integration, Verification, Validation and Qualification Handbook | F24: 5.2 6.1 6.1 6.1 | G24: 87201255-PRJ-GRP-EN 87201334-DDQ-GRP-EN 87201508-DDQ-GRP-EN 83410345-DDQ-CAN-EN
B25: TCTS WBS.3.7 | C25: Product / Platform | D25: Platform & Product activities and commitment of the Product team towards the Project. | E25: Manage a Work Package | F25: 5.2 | G25: 87201255-PRJ-GRP-EN
B26: TCTS WBS.4 | C26: Data Communication Systems
B27: TCTS WBS.4.1 | C27: Cyber IT / DCS / Network / Tools Design | D27: specialized domain knowledge on cybyersecurity engineering and assist system and other engineers develop and incorporate security design and functions into their solutions. | E27: URS Cybersecurity Instruction | F27: 0.1 | G27: 83410893-GOV-CAN-EN
B28: TCTS WBS.4.2 | C28: DCS Test and Verification
B29: TCTS WBS.4.3 | C29: Cyber Security Assurance | D29: Provides domain knowledge for conducting cybersecurity risk assessment, technical vulnerability assessment and penetration testing, security site acceptance testing
B30: TCTS WBS.5 | C30: Solutions Deployment | E30: Site Deployment Handbook | F30: 6.1 | G30: 83410470-DDQ-CAN-EN
B31: TCTS WBS.5.1 | C31: Deployment Project Management | D31: -WPM activities -Produce Operations & Maintenance Manuals Anything related to customer training -Activities related to any document to be ECN'd and drawings and SW archiving | E31: Manage a Work Package Site Deployment Handbook Guideline | F31: 5.2 | G31: 87201255-PRJ-GRP-EN
B32: TCTS WBS.5.2 | C32: Installation Design | D32: WPM activities | E32: Manage a Work Package | F32: 5.2 | G32: 87201255-PRJ-GRP-EN
B33: TCTS WBS.5.3 | C33: Warehouse & Logistic | D33: WPM activities | E33: Manage a Work Package | F33: 5.2 | G33: 87201255-PRJ-GRP-EN
B34: TCTS WBS.5.4 | C34: Installation | D34: All Wayside, Central & vehicle installation activities, including surveys, subcontractors management | E34: Site Deployment Handbook Acceptance Review Description | F34: 8.1 5.2 | G34: 83410470-SER-CAN-EN 87202030-PRJ-GRP-EN
B35: TCTS WBS.5.5 | C35: Test & Commissioning | D35: All Vehicle SPICO & SAT & commissionning activities, subbcontractors management, DPICO & SAT & commissionning, .. | E35: Site Deployment Handbook Acceptance Review Description | F35: 8.1 5.2 | G35: 83410470-SER-CAN-EN 87202030-PRJ-GRP-EN
B36: TCTS WBS.5.6 | C36: Decomissioning | D36: WPM activities | E36: Manage a Work Package | F36: 5.2 | G36: 87201255-PRJ-GRP-EN
B37: TCTS WBS.5.7 | C37: HSE | D37: All Health, Safety & Environment activities | E37: Project/Product HSE plan HSE Management System Guide (Sites & Operations) | F37: 9.02 | G37: 87204117-HSE-GRP-EN 87200107-HSE-GRP-EN
B38: TCTS WBS.5.8 | C38: Track and Civil Works | D38: WPM activities | E38: Manage a Work Package | F38: 5.2 | G38: 87201255-PRJ-GRP-EN
B39: TCTS WBS.5.9 | C39: Training Delivery | D39: -Produce Operations & Maintenance Manuals Anything related to customer training | E39: Manage a Work Package Produce Customer Documentation Provide Customer training | F39: 5.2 8.1 8.1 | G39: 87201423-SER-GRP-EN 87201424-SER-CAN-EN 83410362-DOC-CAN-EN | I39: Available on GTS MS Processes ->8.1 SER -> Produce Customer Documentation -> Print Available on GTS MS Processes ->8.1 SER -> Provide Customer training -> Print
B40: TCTS WBS.6 | C40: Service Delivery | E40: Prepare and Deliver Customer Service CAN | F40: 8.1 | G40: 87201420-SER-GRP-EN | I40: Available on GTS MS Processes -> 8.1 SER -> Print
B41: TCTS WBS.6.1 | C41: Test & Commissioning Support | D41: WPM activities | E41: Manage a Work Package | F41: 5.2 | G41: 87201255-PRJ-GRP-EN 83410470-SER- CAN-EN
...

Sheet Generic OBS
B1: Generic OBS for URS Projects
B2: ='Template change log & approval'!$B$7&" - "&'Template change log & approval'!$G$7 -> -
G48: Hitachi Rail – Internal
G49: This document may not be reproduced, modified, adapted, published, translated, in any way, in whole or in part, or disclosed to a third party without the prior written consent of HITACHI RAIL
G50: © Hitachi Rail Limited 2025. All rights reserved. | K50: Template: 87201589-QCI-GRP-EN-014

Sheet Generic CBS
B1: Generic CBS for URS Projects
B2: ='Template change log & approval'!$B$7&" - "&'Template change log & approval'!$G$7 -> -
I72: Hitachi Rail – Internal
I73: This document may not be reproduced, modified, adapted, published, translated, in any way, in whole or in part, or disclosed to a third party without the prior written consent of HITACHI RAIL
I74: © Hitachi Rail Limited 2025. All rights reserved. | M74: Template: 87201589-QCI-GRP-EN-014

Sheet Generic RACI
B1: Generic RACI Matrix for URS Projects
B2: ='Template change log & approval'!$B$7&" - "&'Template change log & approval'!$G$7 -> -
D4: Program Management | E4: Program Management | F4: Cost Control Management | G4: Contract Management | H4: Procurement | I4: Quality Assurance | J4: Publications & Archives | K4: Technical Safety | L4: Safety Engineering | M4: Safety Assurance | N4: RAMT | O4: Independent Validation | P4: Solution Engineering | Q4: Project Engineering Mgt | R4: Solution CM | S4: Systems Engineering | T4: Software Engineering | U4: Hardware Engineering | V4: Integration, Test and Verification | W4: Product / Platform | X4: Data Communication Systems | Y4: Cyber IT / DCS / Network / Tools Design | Z4: DCS Test and Verification | AA4: Cyber Security Assurance | AB4: Solutions Deployment | AC4: Deployment Project Management | AD4: Infrastructure Design | AE4: Warehouse & Logistic | AF4: Installation | AG4: Test & Comissioning | AH4: Decommissioning | AI4: HSE | AJ4: Track and Civil Works | AK4: Training Delivery | AL4: Service Delivery | AM4: Warranty Support | AN4: Life Cycle Support | AO4: Other Services
B6: Project Manager | E6: A/R | F6: A | G6: A | H6: A | I6: A | J6: A | L6: I | M6: I | N6: I | O6: I | Q6: I | R6: I | S6: I | T6: I | U6: I | V6: I | W6: I | Y6: I (WP3) / A (WP4) | Z6: I (WP3) / A (WP4) | AA6: I (WP3) / A (WP4) | AC6: I | AD6: I | AE6: I | AF6: I | AG6: I | AH6: I | AI6: I | AJ6: I | AK6: I | AM6: I | AN6: I | AO6: I
B8: Project Office Manager | E8: R | F8: C | J8: C
B10: Data Manager | E10: R | J10: C
B12: Publications WPM | E12: C | J12: R | AK12: R
B14: Administrative Assistant | E14: C
B16: Project Planner | E16: R | F16: C | Q16: I | R16: I
B18: Risk & Opportunity Manager | E18: R
B20: Project Financial Controller | E20: R | F20: R
B22: Contract Manager | E22: C | G22: R
B24: Acquisition Project Manager | E24: C | H24: R | AD24: C | AE24: R
B26: Quality Assurance Manager | E26: C | I26: R
B28: Project Configuration Manager | E28: C | J28: C | Q28: C | R28: R | S28: C | T28: C | U28: C | V28: C | W28: C | Y28: C | Z28: C | AC28: C | AD28: C | AN28: C
B30: Safety Assurance Manager | E30: C | M30: A/R
B32: Project Safety Manager | E32: C | L32: A/R | N32: C
B34: RAM Lead | E34: C | N34: A/R
B36: Localized Safety Manager | E36: C | L36: R
B38: Safety Authority | E38: C | O38: C
B40: Independent Validator | E40: C | O40: A/R
B42: Independent SW Assessor | E42: C | M42: R
B44: Independent Safety Assessor | E44: C | M44: R
B46: Cyber Security Authority | E46: C | V46: C | Y46: C | AA46: A
B48: Project Cybersecurity Manager (PCM) | E48: C | AA48: R
B50: Chief Engineering Architect | E50: C | J50: C | Q50: A | R50: A | S50: A | T50: A | U50: A | V50: A | W50: A | Y50: I (WP4) / A (WP3) | Z50: I (WP4) / A (WP3)
B52: Solution Engineering Manager | E52: C | J52: C | Q52: R | R52: A | S52: A | T52: A | U52: A | V52: A | W52: A | Y52: I (WP4) / A (WP3) | Z52: I (WP4) / A (WP3)
B54: Solution Engineering Manager Product/Platform | E54: C | W54: R
B56: System WPM | E56: C | S56: R | V56: C | Y56: C
B58: Data Communication Systems Manager | E58: C | Y58: R | Z58: R | AA58: R
B60: Architect | E60: C | L60: C | N60: C | S60: C | V60: C | Y60: C
B62: System Engineers | E62: C | J62: C | L62: C | N62: C | S62: C | V62: C | Y62: C
B64: Project Design Authority | E64: C | J64: C | L64: C | N64: C | O64: C | Q64: R | R64: R | S64: C | T64: C | U64: C | V64: C | Y64: C | Z64: C
B66: Project Design Authority Product/Platform | E66: C | W66: R
B68: HW Engineering Manager | E68: C | U68: R | AF68: I | AG68: I | AH68: I | AJ68: I
B70: HW Architect | E70: C | N70: C | U70: C
B72: HW Engineers | E72: C | U72: C
B74: HW CM Controller | E74: C | J74: C | L74: C | Q74: C | R74: C | U74: C | V74: C | Y74: C | AC74: C | AD74: C | AE74: C
B76: SW Engineering Manager | E76: C | T76: R
B78: SW Architect | E78: C | L78: C | T78: C
...
